Workbook

Sheet Master Catalog Tracker
A1: MASTER CATALOG TRACKER
A2: Multi-distributor price verification & QA workflow — anonymized portfolio sample (100 items)
A4: ITEM RECORD | J4: NORTHGATE BOOK DISTRIBUTION | S4: HARROW & VALE WHOLESALE | AB4: WRENFIELD MEDIA SUPPLY | AK4: SOLSTICE BOOK TRADE | AT4: RESOLUTION
A5: Item Code | B5: Title | C5: Author | D5: Primary Publisher | E5: Category | F5: Sub-Category | G5: Verified in System | H5: Date Added | I5: Added By | J5: Link | K5: SKU | L5: Catalog Price | M5: Live Price | N5: Qty (Sold By) | O5: Unit Price | P5: Manual Match? | Q5: Status | R5: Remark | S5: Link | T5: SKU | U5: Catalog Price | V5: Live Price | W5: Qty (Sold By) | X5: Unit Price | Y5: Manual Match? | Z5: Status | AA5: Remark | AB5: Link | AC5: SKU | AD5: Catalog Price | AE5: Live Price | AF5: Qty (Sold By) | AG5: Unit Price | AH5: Manual Match? | AI5: Status | AJ5: Remark | AK5: Link | AL5: SKU | AM5: Catalog Price | AN5: Live Price | AO5: Qty (Sold By) | AP5: Unit Price | AQ5: Manual Match? | AR5: Status | AS5: Remark | AT5: Final Catalog Status | AU5: Updated By
A6: BK1000 | B6: The Drifting Lighthouse | C6: Rowan Amari | D6: Larkspur & Co. | E6: Book Care Supplies | F6: Preservation Sleeves | G6: Yes | H6: 2025-12-26 | I6: Mika | J6: https://northgatebooks.example/catalog/BK1000 | K6: NOR-22255 | L6: 50.21 | M6: 70.89 | N6: 1 | O6: =IFERROR(M6/N6,0) -> 70.89 | P6: No | Q6: Unavailable - no comparable listing found | R6: Price increased since last catalog cycle. | S6: https://harrowbooks.example/catalog/BK1000 | T6: HAR-20837 | U6: 50.21 | V6: 59.25 | W6: 10 | X6: =IFERROR(V6/W6,0) -> 5.925 | Y6: No | Z6: Approved | AA6: No exact match; used closest available format. | AB6: https://wrenfieldbooks.example/catalog/BK1000 | AC6: WRE-15577 | AD6: 50.21 | AE6: 61.13 | AF6: 10 | AG6: =IFERROR(AE6/AF6,0) -> 6.113 | AH6: No | AI6: Approved | AJ6: Alternate imprint used; no direct equivalent found. | AK6: https://solsticebooks.example/catalog/BK1000 | AL6: SOL-45532 | AM6: 50.21 | AN6: 55.76 | AO6: 10 | AP6: =IFERROR(AN6/AO6,0) -> 5.576 | AQ6: No | AR6: Unavailable - no comparable listing found | AS6: Price unchanged from prior review. | AT6: Catalog Entry Complete | AU6: Mika
A7: BK1001 | B7: The Midnight Ledger | C7: Rowan Fennimore | D7: Candlewright Books | E7: Poetry & Classics | F7: Poetry Anthologies | G7: Yes | H7: 2025-12-06 | I7: Mika | J7: https://northgatebooks.example/catalog/BK1001 | K7: NOR-85082 | L7: 60.19 | M7: 68.53 | N7: 24 | O7: =IFERROR(M7/N7,0) -> 2.8554167 | P7: No | Q7: Approved, pending re-check next cycle | R7: Price increased since last catalog cycle. | S7: https://harrowbooks.example/catalog/BK1001 | T7: HAR-90134 | U7: 60.19 | V7: 68.84 | W7: 24 | X7: =IFERROR(V7/W7,0) -> 2.8683333 | Y7: No | Z7: Approved, pending re-check next cycle | AA7: Bundled pricing applied; unit price recalculated. | AB7: https://wrenfieldbooks.example/catalog/BK1001 | AC7: WRE-41194 | AD7: 60.19 | AE7: 64.87 | AF7: 24 | AG7: =IFERROR(AE7/AF7,0) -> 2.7029167 | AH7: No | AI7: Approved, pending re-check next cycle | AJ7: New printing released; ISBN updated. | AK7: https://solsticebooks.example/catalog/BK1001 | AL7: SOL-68540 | AM7: 60.19 | AN7: 67.8 | AO7: 1 | AP7: =IFERROR(AN7/AO7,0) -> 67.8 | AQ7: No | AR7: Rejected, closest match only | AS7: Bundled pricing applied; unit price recalculated. | AT7: Catalog Entry Complete | AU7: Mika
A8: BK1002 | B8: The Paper Signal | C8: Felix Holloway | D8: Graymoor Editions | E8: Mystery & Thriller | F8: Psychological Thriller | G8: Yes | H8: 2025-12-23 | I8: Mika | J8: https://northgatebooks.example/catalog/BK1002 | K8: NOR-67240 | L8: 79.22 | M8: 101.95 | N8: 50 | O8: =IFERROR(M8/N8,0) -> 2.039 | P8: No | Q8: Unavailable - no comparable listing found | R8: New printing released; ISBN updated. | S8: https://harrowbooks.example/catalog/BK1002 | T8: HAR-39041 | U8: 79.22 | V8: 98.44 | W8: 25 | X8: =IFERROR(V8/W8,0) -> 3.9376 | Y8: No | Z8: Approved - price verified | AA8: Bundled pricing applied; unit price recalculated. | AB8: https://wrenfieldbooks.example/catalog/BK1002 | AC8: WRE-55793 | AD8: 79.22 | AE8: 83.7 | AF8: 100 | AG8: =IFERROR(AE8/AF8,0) -> 0.837 | AH8: No | AI8: Approved, pending re-check next cycle | AJ8: Manual entry required - barcode mismatch in system. | AK8: https://solsticebooks.example/catalog/BK1002 | AL8: SOL-29194 | AM8: 79.22 | AN8: 84.22 | AO8: 12 | AP8: =IFERROR(AN8/AO8,0) -> 7.0183333 | AQ8: No | AR8: Rejected - format mismatch | AS8: New printing released; ISBN updated. | AT8: Catalog Entry Complete | AU8: Mika
A9: BK1003 | B9: The Gilded River | C9: Ines Novak | D9: Milltide Editions | E9: Book Care Supplies | F9: Preservation Sleeves | G9: No | H9: 2025-12-06 | I9: Seann | J9: https://northgatebooks.example/catalog/BK1003 | K9: NOR-53480 | L9: 55.25 | M9: 76.36 | N9: 5 | O9: =IFERROR(M9/N9,0) -> 15.272 | P9: No | Q9: Rejected - edition discontinued | R9: Alternate imprint used; no direct equivalent found. | S9: https://harrowbooks.example/catalog/BK1003 | T9: HAR-17038 | U9: 55.25 | V9: 64.47 | W9: 50 | X9: =IFERROR(V9/W9,0) -> 1.2894 | Y9: No | Z9: Rejected, closest match only | AA9: Bundled pricing applied; unit price recalculated. | AB9: https://wrenfieldbooks.example/catalog/BK1003 | AC9: WRE-61996 | AD9: 55.25 | AE9: 58.23 | AF9: 1 | AG9: =IFERROR(AE9/AF9,0) -> 58.23 | AH9: No | AI9: Approved, pending re-check next cycle | AJ9: Quantity break pricing verified against distributor site. | AK9: https://solsticebooks.example/catalog/BK1003 | AL9: SOL-59207 | AM9: 55.25 | AN9: 77.23 | AO9: 10 | AP9: =IFERROR(AN9/AO9,0) -> 7.723 | AQ9: No | AR9: Approved - price verified | AS9: Alternate imprint used; no direct equivalent found. | AT9: Pending Re-Approval | AU9: Seann
A10: BK1004 | B10: The Wandering Coastline | C10: Naomi Amari | D10: Candlewright Books | E10: Children's & YA | F10: Young Adult | G10: No | H10: 2025-12-24 | I10: Mika | J10: https://northgatebooks.example/catalog/BK1004 | K10: NOR-56076 | L10: 4.88 | M10: 6.27 | N10: 1 | O10: =IFERROR(M10/N10,0) -> 6.27 | P10: Yes | Q10: Rejected, closest match only | R10: Cover format changed (paperback to hardcover). | S10: https://harrowbooks.example/catalog/BK1004 | T10: HAR-82534 | U10: 4.88 | V10: 6.46 | W10: 1 | X10: =IFERROR(V10/W10,0) -> 6.46 | Y10: Yes | Z10: Approved | AA10: Manual entry required - barcode mismatch in system. | AB10: https://wrenfieldbooks.example/catalog/BK1004 | AC10: WRE-96298 | AD10: 4.88 | AE10: 5.8 | AF10: 24 | AG10: =IFERROR(AE10/AF10,0) -> 0.24166667 | AH10: No | AI10: Rejected, closest match only | AJ10: Price increased since last catalog cycle. | AK10: https://solsticebooks.example/catalog/BK1004 | AL10: SOL-41370 | AM10: 4.88 | AN10: 6.3 | AO10: 100 | AP10: =IFERROR(AN10/AO10,0) -> 0.063 | AQ10: Yes | AR10: Rejected - edition discontinued | AS10: Price increased since last catalog cycle. | AT10: Pending Re-Approval | AU10: Mika
A11: BK1005 | B11: The Endless Clockwork | C11: Naomi Marchetti | D11: Larkspur & Co. | E11: Mystery & Thriller | F11: Cozy Mystery | G11: Yes | H11: 2025-12-20 | I11: Mika | J11: https://northgatebooks.example/catalog/BK1005 | K11: NOR-15130 | L11: 72.86 | M11: 94.94 | N11: 1 | O11: =IFERROR(M11/N11,0) -> 94.94 | P11: No | Q11: Approved, pending re-check next cycle | R11: No exact match; used closest available format. | S11: https://harrowbooks.example/catalog/BK1005 | T11: HAR-57696 | U11: 72.86 | V11: 79.13 | W11: 1 | X11: =IFERROR(V11/W11,0) -> 79.13 | Y11: No | Z11: Approved, pending re-check next cycle | AA11: No exact match; used closest available format. | AB11: https://wrenfieldbooks.example/catalog/BK1005 | AC11: WRE-18639 | AD11: 72.86 | AE11: 82.65 | AF11: 25 | AG11: =IFERROR(AE11/AF11,0) -> 3.306 | AH11: No | AI11: Rejected - format mismatch | AJ11: Bundled pricing applied; unit price recalculated. | AK11: https://solsticebooks.example/catalog/BK1005 | AL11: SOL-29709 | AM11: 72.86 | AN11: 81.43 | AO11: 1 | AP11: =IFERROR(AN11/AO11,0) -> 81.43 | AQ11: No | AR11: Approved, pending re-check next cycle | AS11: Quantity break pricing verified against distributor site. | AT11: Catalog Entry Complete | AU11: Mika
A12: BK1006 | B12: The Winter's Bridge | C12: Naomi Kessler | D12: Milltide Editions | E12: Fiction | F12: Contemporary Fiction | G12: Yes | H12: 2025-12-04 | I12: Mika | J12: https://northgatebooks.example/catalog/BK1006 | K12: NOR-67560 | L12: 21.42 | M12: 22.3 | N12: 1 | O12: =IFERROR(M12/N12,0) -> 22.3 | P12: No | Q12: Rejected, closest match only | R12: Distributor discontinued this edition. | S12: https://harrowbooks.example/catalog/BK1006 | T12: HAR-80776 | U12: 21.42 | V12: 22.85 | W12: 1 | X12: =IFERROR(V12/W12,0) -> 22.85 | Y12: No | Z12: Approved - price verified | AA12: Alternate imprint used; no direct equivalent found. | AB12: https://wrenfieldbooks.example/catalog/BK1006 | AC12: WRE-13390 | AD12: 21.42 | AE12: 25.98 | AF12: 1 | AG12: =IFERROR(AE12/AF12,0) -> 25.98 | AH12: No | AI12: Rejected, closest match only | AJ12: Distributor discontinued this edition. | AK12: https://solsticebooks.example/catalog/BK1006 | AL12: SOL-85529 | AM12: 21.42 | AN12: 22.57 | AO12: 1 | AP12: =IFERROR(AN12/AO12,0) -> 22.57 | AQ12: No | AR12: Approved | AS12: Distributor discontinued this edition. | AT12: Catalog Entry Complete | AU12: Mika
A13: BK1007 | B13: The Wandering Archive | C13: Marcus Amari | D13: Ashwell & Kin Press | E13: Poetry & Classics | F13: Poetry Anthologies | G13: No | H13: 2025-12-07 | I13: Seann | J13: https://northgatebooks.example/catalog/BK1007 | K13: NOR-18783 | L13: 13.9 | M13: 14.23 | N13: 1 | O13: =IFERROR(M13/N13,0) -> 14.23 | P13: Yes | Q13: Rejected - edition discontinued | R13: Bundled pricing applied; unit price recalculated. | S13: https://harrowbooks.example/catalog/BK1007 | T13: HAR-70051 | U13: 13.9 | V13: 13.64 | W13: 1 | X13: =IFERROR(V13/W13,0) -> 13.64 | Y13: No | Z13: Approved - price verified | AA13: Alternate imprint used; no direct equivalent found. | AB13: https://wrenfieldbooks.example/catalog/BK1007 | AC13: WRE-84264 | AD13: 13.9 | AE13: 17.9 | AF13: 100 | AG13: =IFERROR(AE13/AF13,0) -> 0.179 | AH13: No | AI13: Approved | AJ13: No exact match; used closest available format. | AK13: https://solsticebooks.example/catalog/BK1007 | AL13: SOL-23237 | AM13: 13.9 | AN13: 16.21 | AO13: 1 | AP13: =IFERROR(AN13/AO13,0) -> 16.21 | AQ13: Yes | AR13: Unavailable - no comparable listing found | AS13: Quantity break pricing verified against distributor site. | AT13: Catalog Entry Complete | AU13: Seann
A14: BK1008 | B14: The Paper Ledger | C14: Callum Bergstrom | D14: Milltide Editions | E14: Collector's Editions | F14: Anniversary Reprints | G14: No | H14: 2025-12-16 | I14: Seann | J14: https://northgatebooks.example/catalog/BK1008 | K14: NOR-73518 | L14: 50.77 | M14: 54.96 | N14: 50 | O14: =IFERROR(M14/N14,0) -> 1.0992 | P14: No | Q14: Approved - price verified | R14: Price increased since last catalog cycle. | S14: https://harrowbooks.example/catalog/BK1008 | T14: HAR-99744 | U14: 50.77 | V14: 52.03 | W14: 12 | X14: =IFERROR(V14/W14,0) -> 4.3358333 | Y14: No | Z14: Approved - price verified | AA14: Cover format changed (paperback to hardcover). | AB14: https://wrenfieldbooks.example/catalog/BK1008 | AC14: WRE-14044 | AD14: 50.77 | AE14: 58.86 | AF14: 12 | AG14: =IFERROR(AE14/AF14,0) -> 4.905 | AH14: No | AI14: Approved | AJ14: Quantity break pricing verified against distributor site. | AK14: https://solsticebooks.example/catalog/BK1008 | AL14: SOL-69942 | AM14: 50.77 | AN14: 64.7 | AO14: 1 | AP14: =IFERROR(AN14/AO14,0) -> 64.7 | AQ14: No | AR14: Approved - price verified | AS14: No exact match; used closest available format. | AT14: Deleted (Outdated) | AU14: Seann
A15: BK1009 | B15: The Autumn's Garden | C15: Aldous Delacroix | D15: Willowmere Books | E15: Book Care Supplies | F15: Dust Jacket Covers | G15: Yes | H15: 2025-12-15 | I15: Mika | J15: https://northgatebooks.example/catalog/BK1009 | K15: NOR-65534 | L15: 66.2 | M15: 75.64 | N15: 50 | O15: =IFERROR(M15/N15,0) -> 1.5128 | P15: No | Q15: Approved | R15: Price increased since last catalog cycle. | S15: https://harrowbooks.example/catalog/BK1009 | T15: HAR-14159 | U15: 66.2 | V15: 74.33 | W15: 1 | X15: =IFERROR(V15/W15,0) -> 74.33 | Y15: Yes | Z15: Unavailable - no comparable listing found | AA15: Price unchanged from prior review. | AB15: https://wrenfieldbooks.example/catalog/BK1009 | AC15: WRE-59081 | AD15: 66.2 | AE15: 72.87 | AF15: 1 | AG15: =IFERROR(AE15/AF15,0) -> 72.87 | AH15: No | AI15: Unavailable - no comparable listing found | AJ15: Cover format changed (paperback to hardcover). | AK15: https://solsticebooks.example/catalog/BK1009 | AL15: SOL-27431 | AM15: 66.2 | AN15: 90.86 | AO15: 50 | AP15: =IFERROR(AN15/AO15,0) -> 1.8172 | AQ15: No | AR15: Approved, pending re-check next cycle | AS15: Alternate imprint used; no direct equivalent found. | AT15: Catalog Entry Complete | AU15: Mika
A16: BK1010 | B16: The Distant Meridian | C16: Miriam Delacroix | D16: Ashwell & Kin Press | E16: Fiction | F16: Historical Fiction | G16: Yes | H16: 2025-12-16 | I16: Seann | J16: https://northgatebooks.example/catalog/BK1010 | K16: NOR-80912 | L16: 5.04 | M16: 6.95 | N16: 1 | O16: =IFERROR(M16/N16,0) -> 6.95 | P16: No | Q16: Unavailable - no comparable listing found | R16: Price unchanged from prior review. | S16: https://harrowbooks.example/catalog/BK1010 | T16: HAR-93066 | U16: 5.04 | V16: 5.29 | W16: 10 | X16: =IFERROR(V16/W16,0) -> 0.529 | Y16: Yes | Z16: Rejected - edition discontinued | AA16: New printing released; ISBN updated. | AB16: https://wrenfieldbooks.example/catalog/BK1010 | AC16: WRE-52516 | AD16: 5.04 | AE16: 6.65 | AF16: 1 | AG16: =IFERROR(AE16/AF16,0) -> 6.65 | AH16: No | AI16: Approved | AJ16: Price increased since last catalog cycle. | AK16: https://solsticebooks.example/catalog/BK1010 | AL16: SOL-84177 | AM16: 5.04 | AN16: 6.84 | AO16: 12 | AP16: =IFERROR(AN16/AO16,0) -> 0.57 | AQ16: No | AR16: Approved, pending re-check next cycle | AS16: Cover format changed (paperback to hardcover). | AT16: Catalog Entry Complete | AU16: Seann
A17: BK1011 | B17: The Gilded Signal | C17: Naomi Amari | D17: Corvus Lane Publishing | E17: Academic & Reference | F17: Study Guides | G17: No | H17: 2025-12-15 | I17: Seann | J17: https://northgatebooks.example/catalog/BK1011 | K17: NOR-28098 | L17: 49.76 | M17: 56.88 | N17: 1 | O17: =IFERROR(M17/N17,0) -> 56.88 | P17: No | Q17: Unavailable - no comparable listing found | R17: Price increased since last catalog cycle. | S17: https://harrowbooks.example/catalog/BK1011 | T17: HAR-32699 | U17: 49.76 | V17: 57.19 | W17: 1 | X17: =IFERROR(V17/W17,0) -> 57.19 | Y17: No | Z17: Approved - price verified | AA17: Bundled pricing applied; unit price recalculated. | AB17: https://wrenfieldbooks.example/catalog/BK1011 | AC17: WRE-89963 | AD17: 49.76 | AE17: 56.1 | AF17: 1 | AG17: =IFERROR(AE17/AF17,0) -> 56.1 | AH17: No | AI17: Approved, pending re-check next cycle | AJ17: Distributor discontinued this edition. | AK17: https://solsticebooks.example/catalog/BK1011 | AL17: SOL-47880 | AM17: 49.76 | AN17: 56.55 | AO17: 1 | AP17: =IFERROR(AN17/AO17,0) -> 56.55 | AQ17: No | AR17: Approved | AS17: Distributor discontinued this edition. | AT17: Catalog Entry Complete | AU17: Seann
... A105: BK1099 | B105: The Forgotten Chronicle | C105: Priya Holloway | D105: Willowmere Books | E105: Collector's Editions | F105: Signed Editions | G105: Yes | H105: 2025-12-26 | I105: Mika | J105: https://northgatebooks.example/catalog/BK1099 | K105: NOR-23965 | L105: 57.96 | M105: 63.97 | N105: 1 | O105: =IFERROR(M105/N105,0) -> 63.97 | P105: Yes | Q105: Rejected - edition discontinued | R105: Bundled pricing applied; unit price recalculated. | S105: https://harrowbooks.example/catalog/BK1099 | T105: HAR-27367 | U105: 57.96 | V105: 57.72 | W105: 1 | X105: =IFERROR(V105/W105,0) -> 57.72 | Y105: No | Z105: Approved - price verified | AA105: New printing released; ISBN updated. | AB105: https://wrenfieldbooks.example/catalog/BK1099 | AC105: WRE-13442 | AD105: 57.96 | AE105: 57.63 | AF105: 1 | AG105: =IFERROR(AE105/AF105,0) -> 57.63 | AH105: No | AI105: Approved - price verified | AJ105: New printing released; ISBN updated. | AK105: https://solsticebooks.example/catalog/BK1099 | AL105: SOL-11617 | AM105: 57.96 | AN105: 57.68 | AO105: 1 | AP105: =IFERROR(AN105/AO105,0) -> 57.68 | AQ105: No | AR105: Approved - price verified | AS105: Cover format changed (paperback to hardcover). | AT105: Catalog Entry Complete | AU105: Mika

Sheet Approved Catalog
A1: APPROVED CATALOG
A2: Live view of finalized items — pulls directly from Master Catalog Tracker via formula
A4: Item Code | B4: Title | C4: Author | D4: Category | E4: Catalog Price | F4: Best Live Price | G4: Best Distributor | H4: Savings vs. Catalog
A5: ='Master Catalog Tracker'!A6 -> BK1000 | B5: ='Master Catalog Tracker'!B6 -> The Drifting Lighthouse | C5: ='Master Catalog Tracker'!C6 -> Rowan Amari | D5: ='Master Catalog Tracker'!E6 -> Book Care Supplies | E5: ='Master Catalog Tracker'!L6 -> 50.21 | F5: =MIN('Master Catalog Tracker'!M6,'Master Catalog Tracker'!V6,'Master Catalog Tracker'!AE6,'Master Catalog Tracker'!AN6) -> 55.76 | G5: =IF('Master Catalog Tracker'!M6=F5,"Northgate Book Distribution",IF('Master Catalog Tracker'!V6=F5,"Harrow & Vale Wholesale",IF('Master Catalog Tracker'!AE6=F5,"Wrenfield Media Supply","Solstice Book Trade"))) -> Solstice Book Trade | H5: =E5-F5 -> -5.55
A6: ='Master Catalog Tracker'!A7 -> BK1001 | B6: ='Master Catalog Tracker'!B7 -> The Midnight Ledger | C6: ='Master Catalog Tracker'!C7 -> Rowan Fennimore | D6: ='Master Catalog Tracker'!E7 -> Poetry & Classics | E6: ='Master Catalog Tracker'!L7 -> 60.19 | F6: =MIN('Master Catalog Tracker'!M7,'Master Catalog Tracker'!V7,'Master Catalog Tracker'!AE7,'Master Catalog Tracker'!AN7) -> 64.87 | G6: =IF('Master Catalog Tracker'!M7=F6,"Northgate Book Distribution",IF('Master Catalog Tracker'!V7=F6,"Harrow & Vale Wholesale",IF('Master Catalog Tracker'!AE7=F6,"Wrenfield Media Supply","Solstice Book Trade"))) -> Wrenfield Media Supply | H6: =E6-F6 -> -4.68
A7: ='Master Catalog Tracker'!A8 -> BK1002 | B7: ='Master Catalog Tracker'!B8 -> The Paper Signal | C7: ='Master Catalog Tracker'!C8 -> Felix Holloway | D7: ='Master Catalog Tracker'!E8 -> Mystery & Thriller | E7: ='Master Catalog Tracker'!L8 -> 79.22 | F7: =MIN('Master Catalog Tracker'!M8,'Master Catalog Tracker'!V8,'Master Catalog Tracker'!AE8,'Master Catalog Tracker'!AN8) -> 83.7 | G7: =IF('Master Catalog Tracker'!M8=F7,"Northgate Book Distribution",IF('Master Catalog Tracker'!V8=F7,"Harrow & Vale Wholesale",IF('Master Catalog Tracker'!AE8=F7,"Wrenfield Media Supply","Solstice Book Trade"))) -> Wrenfield Media Supply | H7: =E7-F7 -> -4.48
A8: ='Master Catalog Tracker'!A11 -> BK1005 | B8: ='Master Catalog Tracker'!B11 -> The Endless Clockwork | C8: ='Master Catalog Tracker'!C11 -> Naomi Marchetti | D8: ='Master Catalog Tracker'!E11 -> Mystery & Thriller | E8: ='Master Catalog Tracker'!L11 -> 72.86 | F8: =MIN('Master Catalog Tracker'!M11,'Master Catalog Tracker'!V11,'Master Catalog Tracker'!AE11,'Master Catalog Tracker'!AN11) -> 79.13 | G8: =IF('Master Catalog Tracker'!M11=F8,"Northgate Book Distribution",IF('Master Catalog Tracker'!V11=F8,"Harrow & Vale Wholesale",IF('Master Catalog Tracker'!AE11=F8,"Wrenfield Media Supply","Solstice Book Trade"))) -> Harrow & Vale Wholesale | H8: =E8-F8 -> -6.27
A9: ='Master Catalog Tracker'!A12 -> BK1006 | B9: ='Master Catalog Tracker'!B12 -> The Winter's Bridge | C9: ='Master Catalog Tracker'!C12 -> Naomi Kessler | D9: ='Master Catalog Tracker'!E12 -> Fiction | E9: ='Master Catalog Tracker'!L12 -> 21.42 | F9: =MIN('Master Catalog Tracker'!M12,'Master Catalog Tracker'!V12,'Master Catalog Tracker'!AE12,'Master Catalog Tracker'!AN12) -> 22.3 | G9: =IF('Master Catalog Tracker'!M12=F9,"Northgate Book Distribution",IF('Master Catalog Tracker'!V12=F9,"Harrow & Vale Wholesale",IF('Master Catalog Tracker'!AE12=F9,"Wrenfield Media Supply","Solstice Book Trade"))) -> Northgate Book Distribution | H9: =E9-F9 -> -0.88
A10: ='Master Catalog Tracker'!A13 -> BK1007 | B10: ='Master Catalog Tracker'!B13 -> The Wandering Archive | C10: ='Master Catalog Tracker'!C13 -> Marcus Amari | D10: ='Master Catalog Tracker'!E13 -> Poetry & Classics | E10: ='Master Catalog Tracker'!L13 -> 13.9 | F10: =MIN('Master Catalog Tracker'!M13,'Master Catalog Tracker'!V13,'Master Catalog Tracker'!AE13,'Master Catalog Tracker'!AN13) -> 13.64 | G10: =IF('Master Catalog Tracker'!M13=F10,"Northgate Book Distribution",IF('Master Catalog Tracker'!V13=F10,"Harrow & Vale Wholesale",IF('Master Catalog Tracker'!AE13=F10,"Wrenfield Media Supply","Solstice Book Trade"))) -> Harrow & Vale Wholesale | H10: =E10-F10 -> 0.26
A11: ='Master Catalog Tracker'!A15 -> BK1009 | B11: ='Master Catalog Tracker'!B15 -> The Autumn's Garden | C11: ='Master Catalog Tracker'!C15 -> Aldous Delacroix | D11: ='Master Catalog Tracker'!E15 -> Book Care Supplies | E11: ='Master Catalog Tracker'!L15 -> 66.2 | F11: =MIN('Master Catalog Tracker'!M15,'Master Catalog Tracker'!V15,'Master Catalog Tracker'!AE15,'Master Catalog Tracker'!AN15) -> 72.87 | G11: =IF('Master Catalog Tracker'!M15=F11,"Northgate Book Distribution",IF('Master Catalog Tracker'!V15=F11,"Harrow & Vale Wholesale",IF('Master Catalog Tracker'!AE15=F11,"Wrenfield Media Supply","Solstice Book Trade"))) -> Wrenfield Media Supply | H11: =E11-F11 -> -6.67
A12: ='Master Catalog Tracker'!A16 -> BK1010 | B12: ='Master Catalog Tracker'!B16 -> The Distant Meridian | C12: ='Master Catalog Tracker'!C16 -> Miriam Delacroix | D12: ='Master Catalog Tracker'!E16 -> Fiction | E12: ='Master Catalog Tracker'!L16 -> 5.04 | F12: =MIN('Master Catalog Tracker'!M16,'Master Catalog Tracker'!V16,'Master Catalog Tracker'!AE16,'Master Catalog Tracker'!AN16) -> 5.29 | G12: =IF('Master Catalog Tracker'!M16=F12,"Northgate Book Distribution",IF('Master Catalog Tracker'!V16=F12,"Harrow & Vale Wholesale",IF('Master Catalog Tracker'!AE16=F12,"Wrenfield Media Supply","Solstice Book Trade"))) -> Harrow & Vale Wholesale | H12: =E12-F12 -> -0.25
A13: ='Master Catalog Tracker'!A17 -> BK1011 | B13: ='Master Catalog Tracker'!B17 -> The Gilded Signal | C13: ='Master Catalog Tracker'!C17 -> Naomi Amari | D13: ='Master Catalog Tracker'!E17 -> Academic & Reference | E13: ='Master Catalog Tracker'!L17 -> 49.76 | F13: =MIN('Master Catalog Tracker'!M17,'Master Catalog Tracker'!V17,'Master Catalog Tracker'!AE17,'Master Catalog Tracker'!AN17) -> 56.1 | G13: =IF('Master Catalog Tracker'!M17=F13,"Northgate Book Distribution",IF('Master Catalog Tracker'!V17=F13,"Harrow & Vale Wholesale",IF('Master Catalog Tracker'!AE17=F13,"Wrenfield Media Supply","Solstice Book Trade"))) -> Wrenfield Media Supply | H13: =E13-F13 -> -6.34
A14: ='Master Catalog Tracker'!A18 -> BK1012 | B14: ='Master Catalog Tracker'!B18 -> The Amber Meridian | C14: ='Master Catalog Tracker'!C18 -> Sylvie Sundstrom | D14: ='Master Catalog Tracker'!E18 -> Fiction | E14: ='Master Catalog Tracker'!L18 -> 83.11 | F14: =MIN('Master Catalog Tracker'!M18,'Master Catalog Tracker'!V18,'Master Catalog Tracker'!AE18,'Master Catalog Tracker'!AN18) -> 83.14 | G14: =IF('Master Catalog Tracker'!M18=F14,"Northgate Book Distribution",IF('Master Catalog Tracker'!V18=F14,"Harrow & Vale Wholesale",IF('Master Catalog Tracker'!AE18=F14,"Wrenfield Media Supply","Solstice Book Trade"))) -> Northgate Book Distribution | H14: =E14-F14 -> -0.03
A15: ='Master Catalog Tracker'!A20 -> BK1014 | B15: ='Master Catalog Tracker'!B20 -> The Ember Wren | C15: ='Master Catalog Tracker'!C20 -> Desmond Whitlock | D15: ='Master Catalog Tracker'!E20 -> Author Merch & Apparel | E15: ='Master Catalog Tracker'!L20 -> 81.65 | F15: =MIN('Master Catalog Tracker'!M20,'Master Catalog Tracker'!V20,'Master Catalog Tracker'!AE20,'Master Catalog Tracker'!AN20) -> 80.82 | G15: =IF('Master Catalog Tracker'!M20=F15,"Northgate Book Distribution",IF('Master Catalog Tracker'!V20=F15,"Harrow & Vale Wholesale",IF('Master Catalog Tracker'!AE20=F15,"Wrenfield Media Supply","Solstice Book Trade"))) -> Solstice Book Trade | H15: =E15-F15 -> 0.83
A16: ='Master Catalog Tracker'!A21 -> BK1015 | B16: ='Master Catalog Tracker'!B21 -> The Broken Clockwork | C16: ='Master Catalog Tracker'!C21 -> Tobias Reyes | D16: ='Master Catalog Tracker'!E21 -> Fiction | E16: ='Master Catalog Tracker'!L21 -> 25.51 | F16: =MIN('Master Catalog Tracker'!M21,'Master Catalog Tracker'!V21,'Master Catalog Tracker'!AE21,'Master Catalog Tracker'!AN21) -> 26.96 | G16: =IF('Master Catalog Tracker'!M21=F16,"Northgate Book Distribution",IF('Master Catalog Tracker'!V21=F16,"Harrow & Vale Wholesale",IF('Master Catalog Tracker'!AE21=F16,"Wrenfield Media Supply","Solstice Book Trade"))) -> Wrenfield Media Supply | H16: =E16-F16 -> -1.45
A17: ='Master Catalog Tracker'!A22 -> BK1016 | B17: ='Master Catalog Tracker'!B22 -> The Paper Meridian | C17: ='Master Catalog Tracker'!C22 -> Yara Kessler | D17: ='Master Catalog Tracker'!E22 -> Book Preservation & Storage Supplies | E17: ='Master Catalog Tracker'!L22 -> 25.68 | F17: =MIN('Master Catalog Tracker'!M22,'Master Catalog Tracker'!V22,'Master Catalog Tracker'!AE22,'Master Catalog Tracker'!AN22) -> 28.31 | G17: =IF('Master Catalog Tracker'!M22=F17,"Northgate Book Distribution",IF('Master Catalog Tracker'!V22=F17,"Harrow & Vale Wholesale",IF('Master Catalog Tracker'!AE22=F17,"Wrenfield Media Supply","Solstice Book Trade"))) -> Northgate Book Distribution | H17: =E17-F17 -> -2.63
A18: ='Master Catalog Tracker'!A23 -> BK1017 | B18: ='Master Catalog Tracker'!B23 -> The Bright Threshold | C18: ='Master Catalog Tracker'!C23 -> Desmond Sundstrom | D18: ='Master Catalog Tracker'!E23 -> Fiction | E18: ='Master Catalog Tracker'!L23 -> 72.93 | F18: =MIN('Master Catalog Tracker'!M23,'Master Catalog Tracker'!V23,'Master Catalog Tracker'!AE23,'Master Catalog Tracker'!AN23) -> 89.59 | G18: =IF('Master Catalog Tracker'!M23=F18,"Northgate Book Distribution",IF('Master Catalog Tracker'!V23=F18,"Harrow & Vale Wholesale",IF('Master Catalog Tracker'!AE23=F18,"Wrenfield Media Supply","Solstice Book Trade"))) -> Northgate Book Distribution | H18: =E18-F18 -> -16.66
A19: ='Master Catalog Tracker'!A26 -> BK1020 | B19: ='Master Catalog Tracker'!B26 -> The Winter's Compass | C19: ='Master Catalog Tracker'!C26 -> Priya Sundstrom | D19: ='Master Catalog Tracker'!E26 -> Mystery & Thriller | E19: ='Master Catalog Tracker'!L26 -> 37.89 | F19: =MIN('Master Catalog Tracker'!M26,'Master Catalog Tracker'!V26,'Master Catalog Tracker'!AE26,'Master Catalog Tracker'!AN26) -> 43.74 | G19: =IF('Master Catalog Tracker'!M26=F19,"Northgate Book Distribution",IF('Master Catalog Tracker'!V26=F19,"Harrow & Vale Wholesale",IF('Master Catalog Tracker'!AE26=F19,"Wrenfield Media Supply","Solstice Book Trade"))) -> Northgate Book Distribution | H19: =E19-F19 -> -5.85
A20: ='Master Catalog Tracker'!A28 -> BK1022 | B20: ='Master Catalog Tracker'!B28 -> The Wandering Vineyard | C20: ='Master Catalog Tracker'!C28 -> Desmond Vasquez | D20: ='Master Catalog Tracker'!E28 -> Fiction | E20: ='Master Catalog Tracker'!L28 -> 42.88 | F20: =MIN('Master Catalog Tracker'!M28,'Master Catalog Tracker'!V28,'Master Catalog Tracker'!AE28,'Master Catalog Tracker'!AN28) -> 41.09 | G20: =IF('Master Catalog Tracker'!M28=F20,"Northgate Book Distribution",IF('Master Catalog Tracker'!V28=F20,"Harrow & Vale Wholesale",IF('Master Catalog Tracker'!AE28=F20,"Wrenfield Media Supply","Solstice Book Trade"))) -> Northgate Book Distribution | H20: =E20-F20 -> 1.79
A21: ='Master Catalog Tracker'!A30 -> BK1024 | B21: ='Master Catalog Tracker'!B30 -> The Forgotten Wren | C21: ='Master Catalog Tracker'!C30 -> Sylvie Whitlock | D21: ='Master Catalog Tracker'!E30 -> Fiction | E21: ='Master Catalog Tracker'!L30 -> 72.74 | F21: =MIN('Master Catalog Tracker'!M30,'Master Catalog Tracker'!V30,'Master Catalog Tracker'!AE30,'Master Catalog Tracker'!AN30) -> 77.1 | G21: =IF('Master Catalog Tracker'!M30=F21,"Northgate Book Distribution",IF('Master Catalog Tracker'!V30=F21,"Harrow & Vale Wholesale",IF('Master Catalog Tracker'!AE30=F21,"Wrenfield Media Supply","Solstice Book Trade"))) -> Harrow & Vale Wholesale | H21: =E21-F21 -> -4.36
A22: ='Master Catalog Tracker'!A31 -> BK1025 | B22: ='Master Catalog Tracker'!B31 -> The Last Garden | C22: ='Master Catalog Tracker'!C31 -> Desmond Sundstrom | D22: ='Master Catalog Tracker'!E31 -> Fiction | E22: ='Master Catalog Tracker'!L31 -> 69.39 | F22: =MIN('Master Catalog Tracker'!M31,'Master Catalog Tracker'!V31,'Master Catalog Tracker'!AE31,'Master Catalog Tracker'!AN31) -> 76.78 | G22: =IF('Master Catalog Tracker'!M31=F22,"Northgate Book Distribution",IF('Master Catalog Tracker'!V31=F22,"Harrow & Vale Wholesale",IF('Master Catalog Tracker'!AE31=F22,"Wrenfield Media Supply","Solstice Book Trade"))) -> Harrow & Vale Wholesale | H22: =E22-F22 -> -7.39
A23: ='Master Catalog Tracker'!A32 -> BK1026 | B23: ='Master Catalog Tracker'!B32 -> The Winter's Letters | C23: ='Master Catalog Tracker'!C32 -> Ines Amari | D23: ='Master Catalog Tracker'!E32 -> Collector's Editions | E23: ='Master Catalog Tracker'!L32 -> 12.08 | F23: =MIN('Master Catalog Tracker'!M32,'Master Catalog Tracker'!V32,'Master Catalog Tracker'!AE32,'Master Catalog Tracker'!AN32) -> 11.67 | G23: =IF('Master Catalog Tracker'!M32=F23,"Northgate Book Distribution",IF('Master Catalog Tracker'!V32=F23,"Harrow & Vale Wholesale",IF('Master Catalog Tracker'!AE32=F23,"Wrenfield Media Supply","Solstice Book Trade"))) -> Wrenfield Media Supply | H23: =E23-F23 -> 0.41
A24: ='Master Catalog Tracker'!A33 -> BK1027 | B24: ='Master Catalog Tracker'!B33 -> The Midnight Harbor | C24: ='Master Catalog Tracker'!C33 -> Priya Whitlock | D24: ='Master Catalog Tracker'!E33 -> Book Preservation & Storage Supplies | E24: ='Master Catalog Tracker'!L33 -> 79.03 | F24: =MIN('Master Catalog Tracker'!M33,'Master Catalog Tracker'!V33,'Master Catalog Tracker'!AE33,'Master Catalog Tracker'!AN33) -> 89.21 | G24: =IF('Master Catalog Tracker'!M33=F24,"Northgate Book Distribution",IF('Master Catalog Tracker'!V33=F24,"Harrow & Vale Wholesale",IF('Master Catalog Tracker'!AE33=F24,"Wrenfield Media Supply","Solstice Book Trade"))) -> Northgate Book Distribution | H24: =E24-F24 -> -10.18
A25: ='Master Catalog Tracker'!A34 -> BK1028 | B25: ='Master Catalog Tracker'!B34 -> The Faded Chronicle | C25: ='Master Catalog Tracker'!C34 -> Priya Holloway | D25: ='Master Catalog Tracker'!E34 -> Collector's Editions | E25: ='Master Catalog Tracker'!L34 -> 45.87 | F25: =MIN('Master Catalog Tracker'!M34,'Master Catalog Tracker'!V34,'Master Catalog Tracker'!AE34,'Master Catalog Tracker'!AN34) -> 45.33 | G25: =IF('Master Catalog Tracker'!M34=F25,"Northgate Book Distribution",IF('Master Catalog Tracker'!V34=F25,"Harrow & Vale Wholesale",IF('Master Catalog Tracker'!AE34=F25,"Wrenfield Media Supply","Solstice Book Trade"))) -> Northgate Book Distribution | H25: =E25-F25 -> 0.54
A26: ='Master Catalog Tracker'!A36 -> BK1030 | B26: ='Master Catalog Tracker'!B36 -> The Bright Hourglass | C26: ='Master Catalog Tracker'!C36 -> Tobias Whitlock | D26: ='Master Catalog Tracker'!E36 -> Mystery & Thriller | E26: ='Master Catalog Tracker'!L36 -> 42.13 | F26: =MIN('Master Catalog Tracker'!M36,'Master Catalog Tracker'!V36,'Master Catalog Tracker'!AE36,'Master Catalog Tracker'!AN36) -> 45.38 | G26: =IF('Master Catalog Tracker'!M36=F26,"Northgate Book Distribution",IF('Master Catalog Tracker'!V36=F26,"Harrow & Vale Wholesale",IF('Master Catalog Tracker'!AE36=F26,"Wrenfield Media Supply","Solstice Book Trade"))) -> Wrenfield Media Supply | H26: =E26-F26 -> -3.25
A27: ='Master Catalog Tracker'!A38 -> BK1032 | B27: ='Master Catalog Tracker'!B38 -> The Forgotten Signal | C27: ='Master Catalog Tracker'!C38 -> Aldous Holloway | D27: ='Master Catalog Tracker'!E38 -> Mystery & Thriller | E27: ='Master Catalog Tracker'!L38 -> 12.34 | F27: =MIN('Master Catalog Tracker'!M38,'Master Catalog Tracker'!V38,'Master Catalog Tracker'!AE38,'Master Catalog Tracker'!AN38) -> 12.52 | G27: =IF('Master Catalog Tracker'!M38=F27,"Northgate Book Distribution",IF('Master Catalog Tracker'!V38=F27,"Harrow & Vale Wholesale",IF('Master Catalog Tracker'!AE38=F27,"Wrenfield Media Supply","Solstice Book Trade"))) -> Harrow & Vale Wholesale | H27: =E27-F27 -> -0.18
A28: ='Master Catalog Tracker'!A40 -> BK1034 | B28: ='Master Catalog Tracker'!B40 -> The Forgotten River | C28: ='Master Catalog Tracker'!C40 -> Elena Delacroix | D28: ='Master Catalog Tracker'!E40 -> Audiobooks & Digital | E28: ='Master Catalog Tracker'!L40 -> 7.16 | F28: =MIN('Master Catalog Tracker'!M40,'Master Catalog Tracker'!V40,'Master Catalog Tracker'!AE40,'Master Catalog Tracker'!AN40) -> 7.18 | G28: =IF('Master Catalog Tracker'!M40=F28,"Northgate Book Distribution",IF('Master Catalog Tracker'!V40=F28,"Harrow & Vale Wholesale",IF('Master Catalog Tracker'!AE40=F28,"Wrenfield Media Supply","Solstice Book Trade"))) -> Wrenfield Media Supply | H28: =E28-F28 -> -0.02
A29: ='Master Catalog Tracker'!A41 -> BK1035 | B29: ='Master Catalog Tracker'!B41 -> The Midnight Clockwork | C29: ='Master Catalog Tracker'!C41 -> Miriam Osei | D29: ='Master Catalog Tracker'!E41 -> Poetry & Classics | E29: ='Master Catalog Tracker'!L41 -> 67.75 | F29: =MIN('Master Catalog Tracker'!M41,'Master Catalog Tracker'!V41,'Master Catalog Tracker'!AE41,'Master Catalog Tracker'!AN41) -> 67.8 | G29: =IF('Master Catalog Tracker'!M41=F29,"Northgate Book Distribution",IF('Master Catalog Tracker'!V41=F29,"Harrow & Vale Wholesale",IF('Master Catalog Tracker'!AE41=F29,"Wrenfield Media Supply","Solstice Book Trade"))) -> Harrow & Vale Wholesale | H29: =E29-F29 -> -0.05
A30: ='Master Catalog Tracker'!A42 -> BK1036 | B30: ='Master Catalog Tracker'!B42 -> The Blue Ledger | C30: ='Master Catalog Tracker'!C42 -> Junia Okafor | D30: ='Master Catalog Tracker'!E42 -> Academic & Reference | E30: ='Master Catalog Tracker'!L42 -> 28.31 | F30: =MIN('Master Catalog Tracker'!M42,'Master Catalog Tracker'!V42,'Master Catalog Tracker'!AE42,'Master Catalog Tracker'!AN42) -> 33.5 | G30: =IF('Master Catalog Tracker'!M42=F30,"Northgate Book Distribution",IF('Master Catalog Tracker'!V42=F30,"Harrow & Vale Wholesale",IF('Master Catalog Tracker'!AE42=F30,"Wrenfield Media Supply","Solstice Book Trade"))) -> Northgate Book Distribution | H30: =E30-F30 -> -5.19
A31: ='Master Catalog Tracker'!A43 -> BK1037 | B31: ='Master Catalog Tracker'!B43 -> The Drifting Compass | C31: ='Master Catalog Tracker'!C43 -> Marcus Amari | D31: ='Master Catalog Tracker'!E43 -> Academic & Reference | E31: ='Master Catalog Tracker'!L43 -> 68.94 | F31: =MIN('Master Catalog Tracker'!M43,'Master Catalog Tracker'!V43,'Master Catalog Tracker'!AE43,'Master Catalog Tracker'!AN43) -> 78.14 | G31: =IF('Master Catalog Tracker'!M43=F31,"Northgate Book Distribution",IF('Master Catalog Tracker'!V43=F31,"Harrow & Vale Wholesale",IF('Master Catalog Tracker'!AE43=F31,"Wrenfield Media Supply","Solstice Book Trade"))) -> Northgate Book Distribution | H31: =E31-F31 -> -9.2
A32: ='Master Catalog Tracker'!A45 -> BK1039 | B32: ='Master Catalog Tracker'!B45 -> The Blue Almanac | C32: ='Master Catalog Tracker'!C45 -> Aldous Holloway | D32: ='Master Catalog Tracker'!E45 -> Book Care Supplies | E32: ='Master Catalog Tracker'!L45 -> 41.02 | F32: =MIN('Master Catalog Tracker'!M45,'Master Catalog Tracker'!V45,'Master Catalog Tracker'!AE45,'Master Catalog Tracker'!AN45) -> 43.52 | G32: =IF('Master Catalog Tracker'!M45=F32,"Northgate Book Distribution",IF('Master Catalog Tracker'!V45=F32,"Harrow & Vale Wholesale",IF('Master Catalog Tracker'!AE45=F32,"Wrenfield Media Supply","Solstice Book Trade"))) -> Harrow & Vale Wholesale | H32: =E32-F32 -> -2.5
A33: ='Master Catalog Tracker'!A48 -> BK1042 | B33: ='Master Catalog Tracker'!B48 -> The Autumn's Archive | C33: ='Master Catalog Tracker'!C48 -> Desmond Whitlock | D33: ='Master Catalog Tracker'!E48 -> Mystery & Thriller | E33: ='Master Catalog Tracker'!L48 -> 17.92 | F33: =MIN('Master Catalog Tracker'!M48,'Master Catalog Tracker'!V48,'Master Catalog Tracker'!AE48,'Master Catalog Tracker'!AN48) -> 19.08 | G33: =IF('Master Catalog Tracker'!M48=F33,"Northgate Book Distribution",IF('Master Catalog Tracker'!V48=F33,"Harrow & Vale Wholesale",IF('Master Catalog Tracker'!AE48=F33,"Wrenfield Media Supply","Solstice Book Trade"))) -> Northgate Book Distribution | H33: =E33-F33 -> -1.16
A34: ='Master Catalog Tracker'!A50 -> BK1044 | B34: ='Master Catalog Tracker'!B50 -> The Paper Letters | C34: ='Master Catalog Tracker'!C50 -> Sylvie Bergstrom | D34: ='Master Catalog Tracker'!E50 -> Book Care Supplies | E34: ='Master Catalog Tracker'!L50 -> 29.31 | F34: =MIN('Master Catalog Tracker'!M50,'Master Catalog Tracker'!V50,'Master Catalog Tracker'!AE50,'Master Catalog Tracker'!AN50) -> 33.23 | G34: =IF('Master Catalog Tracker'!M50=F34,"Northgate Book Distribution",IF('Master Catalog Tracker'!V50=F34,"Harrow & Vale Wholesale",IF('Master Catalog Tracker'!AE50=F34,"Wrenfield Media Supply","Solstice Book Trade"))) -> Solstice Book Trade | H34: =E34-F34 -> -3.92
A35: ='Master Catalog Tracker'!A54 -> BK1048 | B35: ='Master Catalog Tracker'!B54 -> The Gilded Archive | C35: ='Master Catalog Tracker'!C54 -> Miriam Reyes | D35: ='Master Catalog Tracker'!E54 -> Children's & YA | E35: ='Master Catalog Tracker'!L54 -> 12.84 | F35: =MIN('Master Catalog Tracker'!M54,'Master Catalog Tracker'!V54,'Master Catalog Tracker'!AE54,'Master Catalog Tracker'!AN54) -> 14.03 | G35: =IF('Master Catalog Tracker'!M54=F35,"Northgate Book Distribution",IF('Master Catalog Tracker'!V54=F35,"Harrow & Vale Wholesale",IF('Master Catalog Tracker'!AE54=F35,"Wrenfield Media Supply","Solstice Book Trade"))) -> Wrenfield Media Supply | H35: =E35-F35 -> -1.19
A36: ='Master Catalog Tracker'!A58 -> BK1052 | B36: ='Master Catalog Tracker'!B58 -> The Blue Harbor | C36: ='Master Catalog Tracker'!C58 -> Miriam Osei | D36: ='Master Catalog Tracker'!E58 -> Collector's Editions | E36: ='Master Catalog Tracker'!L58 -> 32.09 | F36: =MIN('Master Catalog Tracker'!M58,'Master Catalog Tracker'!V58,'Master Catalog Tracker'!AE58,'Master Catalog Tracker'!AN58) -> 36.09 | G36: =IF('Master Catalog Tracker'!M58=F36,"Northgate Book Distribution",IF('Master Catalog Tracker'!V58=F36,"Harrow & Vale Wholesale",IF('Master Catalog Tracker'!AE58=F36,"Wrenfield Media Supply","Solstice Book Trade"))) -> Wrenfield Media Supply | H36: =E36-F36 -> -4
A37: ='Master Catalog Tracker'!A59 -> BK1053 | B37: ='Master Catalog Tracker'!B59 -> The Endless Archive | C37: ='Master Catalog Tracker'!C59 -> Yara Okafor | D37: ='Master Catalog Tracker'!E59 -> Book Preservation & Storage Supplies | E37: ='Master Catalog Tracker'!L59 -> 72.81 | F37: =MIN('Master Catalog Tracker'!M59,'Master Catalog Tracker'!V59,'Master Catalog Tracker'!AE59,'Master Catalog Tracker'!AN59) -> 79.09 | G37: =IF('Master Catalog Tracker'!M59=F37,"Northgate Book Distribution",IF('Master Catalog Tracker'!V59=F37,"Harrow & Vale Wholesale",IF('Master Catalog Tracker'!AE59=F37,"Wrenfield Media Supply","Solstice Book Trade"))) -> Harrow & Vale Wholesale | H37: =E37-F37 -> -6.28
A38: ='Master Catalog Tracker'!A60 -> BK1054 | B38: ='Master Catalog Tracker'!B60 -> The Crooked River | C38: ='Master Catalog Tracker'!C60 -> Odette Sundstrom | D38: ='Master Catalog Tracker'!E60 -> Fiction | E38: ='Master Catalog Tracker'!L60 -> 77.76 | F38: =MIN('Master Catalog Tracker'!M60,'Master Catalog Tracker'!V60,'Master Catalog Tracker'!AE60,'Master Catalog Tracker'!AN60) -> 77.1 | G38: =IF('Master Catalog Tracker'!M60=F38,"Northgate Book Distribution",IF('Master Catalog Tracker'!V60=F38,"Harrow & Vale Wholesale",IF('Master Catalog Tracker'!AE60=F38,"Wrenfield Media Supply","Solstice Book Trade"))) -> Wrenfield Media Supply | H38: =E38-F38 -> 0.66
A39: ='Master Catalog Tracker'!A62 -> BK1056 | B39: ='Master Catalog Tracker'!B62 -> The Amber Meridian | C39: ='Master Catalog Tracker'!C62 -> Sylvie Novak | D39: ='Master Catalog Tracker'!E62 -> Fiction | E39: ='Master Catalog Tracker'!L62 -> 75.92 | F39: =MIN('Master Catalog Tracker'!M62,'Master Catalog Tracker'!V62,'Master Catalog Tracker'!AE62,'Master Catalog Tracker'!AN62) -> 88.82 | G39: =IF('Master Catalog Tracker'!M62=F39,"Northgate Book Distribution",IF('Master Catalog Tracker'!V62=F39,"Harrow & Vale Wholesale",IF('Master Catalog Tracker'!AE62=F39,"Wrenfield Media Supply","Solstice Book Trade"))) -> Northgate Book Distribution | H39: =E39-F39 -> -12.9
A40: ='Master Catalog Tracker'!A63 -> BK1057 | B40: ='Master Catalog Tracker'!B63 -> The Midnight Orchard | C40: ='Master Catalog Tracker'!C63 -> Sylvie Whitlock | D40: ='Master Catalog Tracker'!E63 -> Display Furniture & Shelving | E40: ='Master Catalog Tracker'!L63 -> 46.83 | F40: =MIN('Master Catalog Tracker'!M63,'Master Catalog Tracker'!V63,'Master Catalog Tracker'!AE63,'Master Catalog Tracker'!AN63) -> 57.28 | G40: =IF('Master Catalog Tracker'!M63=F40,"Northgate Book Distribution",IF('Master Catalog Tracker'!V63=F40,"Harrow & Vale Wholesale",IF('Master Catalog Tracker'!AE63=F40,"Wrenfield Media Supply","Solstice Book Trade"))) -> Harrow & Vale Wholesale | H40: =E40-F40 -> -10.45
A41: ='Master Catalog Tracker'!A65 -> BK1059 | B41: ='Master Catalog Tracker'!B65 -> The Ember Meridian | C41: ='Master Catalog Tracker'!C65 -> Rowan Okafor | D41: ='Master Catalog Tracker'!E65 -> Academic & Reference | E41: ='Master Catalog Tracker'!L65 -> 13.73 | F41: =MIN('Master Catalog Tracker'!M65,'Master Catalog Tracker'!V65,'Master Catalog Tracker'!AE65,'Master Catalog Tracker'!AN65) -> 16.6 | G41: =IF('Master Catalog Tracker'!M65=F41,"Northgate Book Distribution",IF('Master Catalog Tracker'!V65=F41,"Harrow & Vale Wholesale",IF('Master Catalog Tracker'!AE65=F41,"Wrenfield Media Supply","Solstice Book Trade"))) -> Solstice Book Trade | H41: =E41-F41 -> -2.87
...

Sheet Dashboard & Automation
A1: DASHBOARD & AUTOMATION
A2: QA progress, reviewer throughput, and one-click actions (wired via Google Apps Script in Sheets)
A4: TOTAL ITEMS | D4: CATALOG COMPLETE | G4: PENDING RE-APPROVAL | J4: DELETED (OUTDATED) | N4: ONE-CLICK ACTIONS
A5: =COUNTA('Master Catalog Tracker'!A6:A105) -> 100 | D5: =COUNTIF('Master Catalog Tracker'!AT6:AT105,"Catalog Entry Complete") -> 59 | G5: =COUNTIF('Master Catalog Tracker'!AT6:AT105,"Pending Re-Approval") -> 16 | J5: =COUNTIF('Master Catalog Tracker'!AT6:AT105,"Deleted (Outdated)") -> 25 | N5: ▶ CLEAN DUPLICATE FORMATTING
N6: Removes redundant conditional-format rules stacked on the same range.
N8: ▶ CLEAR REDUNDANT ROWS
N9: Flags and removes fully-blank or duplicate item-code rows.
A10: ITEMS BY CATEGORY | E10: STATUS BREAKDOWN | H10: REVIEWER PRODUCTIVITY
A11: Category | B11: Count | E11: Status | F11: Count | H11: Reviewer | I11: Items Added | J11: Items Finalized | N11: ▶ REFRESH PROGRESS LOG
A12: Fiction | B12: =COUNTIF('Master Catalog Tracker'!E6:E105,A12) -> 25 | E12: Catalog Entry Complete | F12: =COUNTIF('Master Catalog Tracker'!AT6:AT105,E12) -> 59 | H12: Seann | I12: =COUNTIF('Master Catalog Tracker'!I6:I105,H12) -> 52 | J12: =COUNTIFS('Master Catalog Tracker'!AU6:AU105,H12,'Master Catalog Tracker'!AT6:AT105,"Catalog Entry Complete") -> 30 | N12: Recomputes the daily reviewer log from current Master Tracker data.
A13: Mystery & Thriller | B13: =COUNTIF('Master Catalog Tracker'!E6:E105,A13) -> 16 | E13: Pending Re-Approval | F13: =COUNTIF('Master Catalog Tracker'!AT6:AT105,E13) -> 16 | H13: Mika | I13: =COUNTIF('Master Catalog Tracker'!I6:I105,H13) -> 48 | J13: =COUNTIFS('Master Catalog Tracker'!AU6:AU105,H13,'Master Catalog Tracker'!AT6:AT105,"Catalog Entry Complete") -> 29
A14: Academic & Reference | B14: =COUNTIF('Master Catalog Tracker'!E6:E105,A14) -> 12 | E14: Deleted (Outdated) | F14: =COUNTIF('Master Catalog Tracker'!AT6:AT105,E14) -> 25 | N14: ▶ EXPORT APPROVED CATALOG
A15: Book Care Supplies | B15: =COUNTIF('Master Catalog Tracker'!E6:E105,A15) -> 10 | N15: Rebuilds the Approved Catalog sheet from the latest Final Status column.
A16: Collector's Editions | B16: =COUNTIF('Master Catalog Tracker'!E6:E105,A16) -> 10
A17: Children's & YA | B17: =COUNTIF('Master Catalog Tracker'!E6:E105,A17) -> 10 | N17: These four actions run as one-click buttons once this file is opened in Google Sheets, wired via a companion Apps Script (provided separately).
A18: Poetry & Classics | B18: =COUNTIF('Master Catalog Tracker'!E6:E105,A18) -> 8
A19: Book Preservation & Storage Supplies | B19: =COUNTIF('Master Catalog Tracker'!E6:E105,A19) -> 4
A20: Display Furniture & Shelving | B20: =COUNTIF('Master Catalog Tracker'!E6:E105,A20) -> 2
A21: Audiobooks & Digital | B21: =COUNTIF('Master Catalog Tracker'!E6:E105,A21) -> 1
A22: Storage Cabinets & Cases | B22: =COUNTIF('Master Catalog Tracker'!E6:E105,A22) -> 1
A23: Author Merch & Apparel | B23: =COUNTIF('Master Catalog Tracker'!E6:E105,A23) -> 1
A26: DAILY PROGRESS LOG
A27: Date | B27: Reviewer | C27: Items Logged
A28: 45992 | B28: Mika | C28: =COUNTIFS('Master Catalog Tracker'!H6:H105,A28,'Master Catalog Tracker'!I6:I105,B28) -> 0
A29: 45992 | B29: Seann | C29: =COUNTIFS('Master Catalog Tracker'!H6:H105,A29,'Master Catalog Tracker'!I6:I105,B29) -> 1
A30: 45993 | B30: Mika | C30: =COUNTIFS('Master Catalog Tracker'!H6:H105,A30,'Master Catalog Tracker'!I6:I105,B30) -> 2
A31: 45993 | B31: Seann | C31: =COUNTIFS('Master Catalog Tracker'!H6:H105,A31,'Master Catalog Tracker'!I6:I105,B31) -> 2
A32: 45994 | B32: Mika | C32: =COUNTIFS('Master Catalog Tracker'!H6:H105,A32,'Master Catalog Tracker'!I6:I105,B32) -> 2
A33: 45994 | B33: Seann | C33: =COUNTIFS('Master Catalog Tracker'!H6:H105,A33,'Master Catalog Tracker'!I6:I105,B33) -> 2
A34: 45995 | B34: Mika | C34: =COUNTIFS('Master Catalog Tracker'!H6:H105,A34,'Master Catalog Tracker'!I6:I105,B34) -> 3
A35: 45995 | B35: Seann | C35: =COUNTIFS('Master Catalog Tracker'!H6:H105,A35,'Master Catalog Tracker'!I6:I105,B35) -> 0
A36: 45996 | B36: Mika | C36: =COUNTIFS('Master Catalog Tracker'!H6:H105,A36,'Master Catalog Tracker'!I6:I105,B36) -> 3
A37: 45996 | B37: Seann | C37: =COUNTIFS('Master Catalog Tracker'!H6:H105,A37,'Master Catalog Tracker'!I6:I105,B37) -> 2
A38: 45997 | B38: Mika | C38: =COUNTIFS('Master Catalog Tracker'!H6:H105,A38,'Master Catalog Tracker'!I6:I105,B38) -> 4
A39: 45997 | B39: Seann | C39: =COUNTIFS('Master Catalog Tracker'!H6:H105,A39,'Master Catalog Tracker'!I6:I105,B39) -> 2
A40: 45998 | B40: Mika | C40: =COUNTIFS('Master Catalog Tracker'!H6:H105,A40,'Master Catalog Tracker'!I6:I105,B40) -> 0
A41: 45998 | B41: Seann | C41: =COUNTIFS('Master Catalog Tracker'!H6:H105,A41,'Master Catalog Tracker'!I6:I105,B41) -> 1
A42: 46000 | B42: Mika | C42: =COUNTIFS('Master Catalog Tracker'!H6:H105,A42,'Master Catalog Tracker'!I6:I105,B42) -> 2
A43: 46000 | B43: Seann | C43: =COUNTIFS('Master Catalog Tracker'!H6:H105,A43,'Master Catalog Tracker'!I6:I105,B43) -> 1
A44: 46001 | B44: Mika | C44: =COUNTIFS('Master Catalog Tracker'!H6:H105,A44,'Master Catalog Tracker'!I6:I105,B44) -> 3
...
